- Changed testathors.csv because author id's did not match books
- Added new author id's to booksdatasourcetest.py
- test_author_id_valueError was changed to test_author_id_attributeError to reflect the error that was thrown by the test

Failure 1:

Failure 2:
- books() should throw a value error when the input is not a number
- the resulting failure is the result of a bug in booksdatasource.py
- 
Failure 3:
